Workbook
Name Cash_Sweep: LBO!#REF!
Name Circularity: LBO!$G$21
Name IQ_CH: 110000
Name IQ_CQ: 5000
Name IQ_CY: 10000
Name IQ_DAILY: 500000
Name IQ_FH: 100000
Name IQ_FQ: 500
Name IQ_FY: 1000
Name IQ_LTM: 2000
Name IQ_MONTH: 15000
Name IQ_NTM: 6000
Name IQ_WEEK: 50000
Name IQ_YTD: 3000

Sheet LDN
B5: Calculation | C5: Black
B6: Input | C6: Blue
B9: Company Financials (£m) | C9: 45657 | D9: 46022 | E9: 46387 | F9: 46752 | G9: 47118 | H9: 47483
B10: Revenue | C10: 9.99 | D10: 15.7 | E10: 19 | F10: 22.7 | G10: 27.3 | H10: 32.7
B11: EBITDA | C11: 1.034 | D11: 2.312 | E11: 2.377 | F11: 2.961 | G11: 3.762 | H11: 4.743
B14: Current Shareholdings (Diluted) | F14: Other assumptions
F15: Tax | H15: 0.2
B16: Chairman | C16: 521805.28 | D16: 0.331 | F16: CAPEX | H16: 0.01
B17: CEO | C17: 553334.3 | D17: 0.351 | F17: Working capital | H17: 0.1
B18: Sales Director | C18: 102469.32 | D18: 0.065 | F18: Yield on senior debt | H18: 0.05
B19: Operations Director | C19: 95000.025 | D19: 0.060261958 | F19: Deal fees | H19: 0.015
B20: Head of US | C20: 0 | D20: 0 | F20: Cash at Bank | H20: 2.3
B21: External shareholders | C21: 165000.04 | D21: 0.10466551
B22: Employees | C22: 97999.025 | D22: 0.062164333
B23: Option holders | C23: 40843.011 | D23: 0.025908202
C24: 1576451 | D24: 1

Sheet Valuation Summary
A1: Valuation Comparison
B5: LBO Implied EV/EBITDA | C5: =LBO!H8
B6: DCF Implied EV/EBITDA | C6: =DCF!C6
B7: Public Comps | C7: ='Public Comps'!L27
B8: Precedent Transactions | C8: ='Precedent Transactions'!J23
B10: Median | C10: =MEDIAN(C5:C8)
B14: Note: Median used for Public Comps, Lower Quartile used for Precedent Transactions

Sheet LBO
B1: Visante - LBO Model
A3: X | B3: Assumptions
B5: Inputs | F5: Valuation related | J5: Transaction Timings
B6: Calculation | C6: Black | F6: Entry EBITDA | H6: 2.312 | J6: Financial Year-end | M6: 46022
B7: Input | C7: Blue | F7: Entry Enterprise Value | H7: 19 | J7: Targeted Completion Date | M7: 45930
F8: Implied Multiple | H8: =H7/H6 | J8: Year Fraction | M8: =YEARFRAC(M7,M6)
B9: Operating related | F9: EV | H9: =H7
B10: Tax | D10: 0.2 | F10: Net cash/ (debt) | H10: 2.3
B11: CAPEX | D11: 0.01 | F11: Working Capital Adj. | H11: 0 | I11: << At this stage, assumed to be no adjustment
B12: Working capital | D12: 0.1 | F12: EqV | H12: =H9+H10+H11
B13: Yield on senior debt | D13: 0.05
B14: Cash at Bank (£m) | D14: 2.3 | F14: Debt related | H14: Yield | I14: Split | J14: Maturity
B15: FY30 Revenue Growth | D15: 0.2 | F15: TLA - Ammortising | H15: 0.04 | I15: 0.5 | J15: 7
B16: FY30 EBITDA Margin | D16: 0.14 | F16: TLB - Bullet | H16: 0.06 | I16: 0.5 | J16: 7
B18: Transaction related | F18: Debt Raised (£m) | H18: 5
B19: Deal fees | D19: 0.015
B20: Completion Consideration | D20: =D12+D21
B21: Buyside Fees and Expenses (£m) | D21: 0.555 | F21: Cirularity | G21: Yes
B22: Sweet Equity | D22: 0.25
B23: Pref/ Loan Notes | D23: 0.9
B24: Ordinary Equity | D24: =D20-D18-D22-D23
B25: Loan Note rate | D25: 0.1 | E25: << Assumed PIK
A27: X | B27: Cap Table
B29: Shareholder/ Stakeholder | C29: # Shares | D29: % Holding | E29: Gross Proceeds | F29: Sellers' Fees | G29: Rollover | H29: Rolled Ownership % | I29: Rollover (£m) | J29: Cashout | K29: New capital | L29: NewCo Capital | M29: NewCo LN (£m) | N29: NewCo Equity (£m)
B31: Non Participating
B32: Chairman | C32: 521805.28 | D32: 0.331 | G32: 0
B33: Head of US | C33: 0 | D33: 0 | G33: 0
B34: External shareholders | C34: 165000.04 | D34: 0.10466551 | G34: 0
B36: Visante Management
B37: CEO | C37: 553334.3 | D37: 0.351 | G37: 0.5
B38: Sales Director | C38: 102469.32 | D38: 0.065 | G38: 0.5
B39: Operations Director | C39: 95000.025 | D39: 0.060261958 | G39: 0.5
B41: Visante Employees
B42: Employees | C42: 97999.025 | D42: 0.062164333 | G42: 0.5
B43: Existing Option holders | C43: 40843.011 | D43: 0.025908202 | G43: 0.5
B45: New Capital
B46: XPE | C46: 0 | D46: 0
B47: Sweet Equity | C47: 0 | D47: 0
B48: Debt | C48: 0 | D48: 0
B50: Total
...

Sheet DCF
B1: Visante - DCF Model
A3: x | B3: Assumptions
B5: Perpetuity Growth | C5: 0.02 | E5: Calculation | F5: Black | G5: Completion | I5: 45930
B6: Exit Multiple | C6: =LBO!H8 | E6: Input | F6: Blue | G6: Financial Year-end | I6: 46022
B7: Tax Rate | C7: 0.2 | G7: Year Fraction | I7: 0.25
B8: Long-term Debt/Equity | C8: 0.5
A11: x | B11: WACC
B13: Cost of Debt | C13: =C14*C7
B14: Debt | C14: =C8/(1+C8) | K14: Beta
K15: Computer services | N15: 0.98
B16: Risk Free Rate | C16: =0.04 | K16: Business and consumer services | N16: 0.85
B17: Equity Risk Premium | C17: =0.06 | K17: Information Services | N17: 0.82
B18: Unlevered Beta | C18: =AVERAGE(L11:L13) | K18: Average | N18: 0.88333333
B19: Levered Beta | C19: =C18*(1+(1-C7)*C8)
B20: Cost of Equity | C20: =C16+C19*C17
B21: Equity | C21: =1-C14
B23: Debt + Equity | C23: =C14+C21
B25: Size Premium | C25: =0.03
B27: WACC | C27: =(C13*C14)+(C20*C21)+C25
A30: x | B30: DCF
C32: 46022 | D32: Q425F | E32: 46387 | F32: 46752 | G32: 47118 | H32: 47483 | I32: 47848
B34: Revenue | C34: =LDN!D10*(1-DCF!I7) | D34: =LDN!D10*DCF!I7 | E34: =LDN!E10 | F34: =LDN!F10 | G34: =LDN!G10 | H34: =LDN!H10 | I34: =LDN!I10
B35: Growth
B36: EBITDA | C36: =LDN!D11*(IF(COLUMN()=3,1-DCF!I7,DCF!I7)) | D36: =LDN!D11*(IF(COLUMN()=3,1-DCF!I7,DCF!I7)) | E36: =LDN!E11 | F36: =LDN!F11 | G36: =LDN!G11 | H36: =LDN!H11 | I36: =LDN!I11
B37: Less D&A | C37: =-C34*0.02 | D37: =-D34*0.02 | E37: =-E34*0.02 | F37: =-F34*0.02 | G37: =-G34*0.02 | H37: =-H34*0.02 | I37: =-I34*0.02
B38: EBIT | C38: =C36+C37 | D38: =D36+D37 | E38: =E36+E37 | F38: =F36+F37 | G38: =G36+G37 | H38: =H36+H37 | I38: =I36+I37
B39: Less: Taxes | C39: =-MAX(C38,0)*$C$7 | D39: =-MAX(D38,0)*$C$7 | E39: =-MAX(E38,0)*$C$7 | F39: =-MAX(F38,0)*$C$7 | G39: =-MAX(G38,0)*$C$7 | H39: =-MAX(H38,0)*$C$7 | I39: =-MAX(I38,0)*$C$7
B40: Plus: D&A | C40: =-C37 | D40: =-D37 | E40: =-E37 | F40: =-F37 | G40: =-G37 | H40: =-H37 | I40: =-I37
B41: Less: CapEx | C41: =-C34*0.01 | D41: =-D34*0.01 | E41: =-E34*0.01 | F41: =-F34*0.01 | G41: =-G34*0.01 | H41: =-H34*0.01 | I41: =-I34*0.01
B42: Less: Increase in NWC | C42: =-C34*0.10 | D42: =-D34*0.10 | E42: =-E34*0.10 | F42: =-F34*0.10 | G42: =-G34*0.10 | H42: =-H34*0.10 | I42: =-I34*0.10
B43: Free Cash Fl ow (FCF) | C43: =SUM(C38:C42) | D43: =SUM(D38:D42) | E43: =SUM(E38:E42) | F43: =SUM(F38:F42) | G43: =SUM(G38:G42) | H43: =SUM(H38:H42) | I43: =SUM(I38:I42)
B45: Period | D45: 0.25 | E45: 1.25 | F45: 2.25 | G45: 3.25 | H45: 4.25 | I45: 5.25
B46: Discount Factor | D46: ??? | E46: ??? | F46: ??? | G46: ??? | H46: ??? | I46: ???
B48: PV of FCF | D48: ??? | E48: ??? | F48: ??? | G48: ??? | H48: ??? | I48: ???
B49: Sum of PV of FCF | I49: ???
B52: Enterprise Value - PGM | E52: Enterprise Value - EMM
B53: Terminal Value | C53: ??? | E53: Terminal Value | G53: ???
B54: PV of Terminal Value | C54: ??? | E54: PV of Terminal Value | G54: ???
B55: Cumulative FCF | C55: ??? | E55: Cumulative FCF | G55: ???
B56: Enterprise Value | C56: ??? | E56: Enterprise Value | G56: ???
...

Sheet Public Comps
B2: Visante - Public Comparibles
B4: Calculation | C4: Black
B5: Input | C5: Blue
K7: Valuation Metrics
C8: Price (£) | D8: Shares | E8: Market | F8: Total | G8: Total | H8: Enterprise | I8: Revenue | J8: EBITDA | K8: Revenue | L8: EBITDA | M8: Location | N8: Description
B9: Company | D9: Oustanding (m) | E9: Cap (£m) | F9: Cash | G9: Debt | H9: Value | I9: LYE | J9: LYE | K9: LYE | L9: LYE
B11: Bytes Technology Group plc | C11: 3.722 | D11: 237.62 | E11: =C11*D11 | F11: 113 | G11: 1.94 | H11: =E11+G11-F11 | I11: 217 | J11: 68.64 | K11: =IFERROR(H11/I11,"Undisclosed") | L11: =IFERROR(H11/J11,"Undisclosed") | M11: UK | N11: IT software and hardware distributor with strong managed services, security, and cloud solutions for business customers.
B12: Computacenter plc | C12: 28.46 | D12: 106.24 | E12: =C12*D12 | F12: 489.6 | G12: 136.9 | H12: =E12+G12-F12 | I12: 6965 | J12: 237 | K12: =IFERROR(H12/I12,"Undisclosed") | L12: =IFERROR(H12/J12,"Undisclosed") | M12: UK | N12: Provides IT infrastructure, supply chain management, managed services, and consulting to large organizations.
B13: FDM Group (Holdings) plc | C13: 1.2263 | D13: 109.72 | E13: =C13*D13 | F13: 41 | G13: 22 | H13: =E13+G13-F13 | I13: 258 | J13: 27 | K13: =IFERROR(H13/I13,"Undisclosed") | L13: =IFERROR(H13/J13,"Undisclosed") | M13: UK | N13: Graduate recruitment, IT skills training, and staff augmentation—places consultants with clients on long-term contracts.
B14: Softcat plc | C14: 15.8 | D14: 199.95 | E14: =C14*D14 | F14: 182 | G14: 0 | H14: =E14+G14-F14 | I14: 1458 | J14: 173.21 | K14: =IFERROR(H14/I14,"Undisclosed") | L14: =IFERROR(H14/J14,"Undisclosed") | M14: UK | N14: IT infrastructure reseller with managed services, security, cloud, and software licensing overlays.
B15: TPXimpact Holdings plc | C15: 0.14 | D15: 92.97 | E15: =C15*D15 | F15: 4.65 | G15: 14 | H15: =E15+G15-F15 | I15: 77 | J15: -2.36 | K15: =IFERROR(H15/I15,"Undisclosed") | L15: =IFERROR(H15/J15,"Undisclosed") | M15: UK | N15: Digital consulting for the UK public sector, focusing on cloud, transformation, and gov.uk project delivery.
B16: Kainos Group plc | C16: 9.38 | D16: 119.23 | E16: =C16*D16 | F16: 134 | G16: 5.56 | H16: =E16+G16-F16 | I16: 367 | J16: 43 | K16: =IFERROR(H16/I16,"Undisclosed") | L16: =IFERROR(H16/J16,"Undisclosed") | M16: UK | N16: Kainos Group plc is a United Kingdom-based information technology (IT) provider. The Company operates through three divisions, including Digital Services, Workday Services, and Workday Products.
B17: Cerillion plc | C17: 14.03 | D17: 29.5 | E17: =C17*D17 | F17: 30 | G17: 2.8 | H17: =E17+G17-F17 | I17: 44 | J17: 18 | K17: =IFERROR(H17/I17,"Undisclosed") | L17: =IFERROR(H17/J17,"Undisclosed") | M17: UK | N17: Cerillion plc is a United Kingdom-based software solutions provider for billing, charging and customer relationship management (CRM).
B18: dotdigital Group plc | C18: 0.7092 | D18: 307.8 | E18: =C18*D18 | F18: 36 | G18: 1.78 | H18: =E18+G18-F18 | I18: 79 | J18: 22 | K18: =IFERROR(H18/I18,"Undisclosed") | L18: =IFERROR(H18/J18,"Undisclosed") | M18: UK | N18: Dotdigital Group plc is a United Kingdom-based software-as-a-service (SaaS) provider of an all-in-one customer experience and data platform (CXDP).
B19: Idox plc | C19: 0.7075 | D19: 461.68 | E19: =C19*D19 | F19: 12 | G19: 24 | H19: =E19+G19-F19 | I19: 88 | J19: 22 | K19: =IFERROR(H19/I19,"Undisclosed") | L19: =IFERROR(H19/J19,"Undisclosed") | M19: UK | N19: Idox plc is a supplier of specialist information management software and geospatial data solutions to the public and asset-intensive sectors.
B20: Gamma Communications plc | C20: 9.66 | D20: 92.17 | E20: =C20*D20 | F20: 154 | G20: 7.9 | H20: =E20+G20-F20 | I20: 579 | J20: 124 | K20: =IFERROR(H20/I20,"Undisclosed") | L20: =IFERROR(H20/J20,"Undisclosed") | M20: UK | N20: A UK-based provider of unified communications as a service (UCaaS), telecom, and connectivity solutions. Serving SMEs, large enterprises, and public sector across Europe, Gamma delivers telephony, mobile, broadband, cloud, and collaboration products over its own network infrastructure
B21: Team Internet Group plc | C21: 0.4629 | D21: 246.18 | E21: =C21*D21 | F21: 88 | G21: 189 | H21: =E21+G21-F21 | I21: 803 | J21: 50.2 | K21: =IFERROR(H21/I21,"Undisclosed") | L21: =IFERROR(H21/J21,"Undisclosed") | M21: UK | N21: Formerly CentralNic Group plc, this is a British multinational internet services company. It operates in two main segments: Online Marketing (generating digital advertising and traffic monetization revenue) and Online Presence (providing domain registration, management, and associated services globally).
B22: Datrix Group plc | C22: 1.463788 | D22: 9.81 | E22: =C22*D22 | F22: 5.572976 | G22: 4.303184 | H22: =E22+G22-F22 | I22: 15.8724 | J22: 20.669392 | K22: =IFERROR(H22/I22,"Undisclosed") | L22: =IFERROR(H22/J22,"Undisclosed") | M22: Italy | N22: Datrix SpA is an Italy-based company that provides augmented analytics software and service solutions based on proprietary artificial intelligence (AI) technologies for marketing, sales, publishing and finance purposes.
... B24: Atos SE | C24: 43.499194 | D24: 19.38 | E24: =C24*D24 | F24: 1533.4502 | G24: 2478.7398 | H24: =E24+G24-F24 | I24: 8444.9986 | J24: 2478.7398 | K24: =IFERROR(H24/I24,"Undisclosed") | L24: =IFERROR(H24/J24,"Undisclosed") | M24: France | N24: Multinational IT services and consulting specializing in digital transformation, cloud, cybersecurity, and HPC.
B26: 25th Percentile | L26: =PERCENTILE.INC(L11:L24,0.25)
B27: Median | L27: =MEDIAN(L11:L24)
B28: 75th Percentile | L28: =PERCENTILE.INC(L11:L24,0.75)
B30: Exchange rate used (Eur/GBP) | C30: 0.8818
B31: Financial Data from Financial Times
B32: Cash, debt, revenue and EBITDA based on latest Year-end information available

Sheet Precedent Transactions
B1: Visante - Precedent Transactions
B3: Year | C3: Target Name | D3: Country | E3: Acquirer | F3: Deal Value (£m) | G3: Target Revenue (£m) | H3: Target EBITDA (£m) | I3: EV/Revenue Multiple | J3: EV/EBITDA Multiple | K3: Business Focus
B4: 2025 | C4: Oakland Group Services | D4: UK | E4: Softcat plc | F4: 8 | G4: 10 | H4: 1.8 | I4: =IFERROR(F4/G4,"Undisclosed") | J4: =IFERROR(F4/H4,"Undisclosed") | K4: Data & AI strategy consulting
B5: 2025 | C5: Fox Crypto | D5: UK | E5: CR Group Nordic AB | F5: 65.6 | G5: 23 | H5: 4 | I5: =IFERROR(F5/G5,"Undisclosed") | J5: =IFERROR(F5/H5,"Undisclosed") | K5: Cryptographic products
B6: 2020 | C6: Context Information Security | D6: UK | E6: Accenture plc | F6: 107 | G6: 60 | H6: 2 | I6: =IFERROR(F6/G6,"Undisclosed") | J6: =IFERROR(F6/H6,"Undisclosed") | K6: Cybersecurity consulting
B7: 2024 | C7: Elastacloud | D7: UK | E7: Acora | F7: Undisclosed | G7: Small | H7: Undisclosed | I7: =IFERROR(F7/G7,"Undisclosed") | J7: =IFERROR(F7/H7,"Undisclosed") | K7: Data science & AI (Microsoft Azure)
B8: 2025 | C8: Risk Crew | D8: UK | E8: Red Helix (LDC-backed) | F8: Undisclosed | G8: Small | H8: Undisclosed | I8: =IFERROR(F8/G8,"Undisclosed") | J8: =IFERROR(F8/H8,"Undisclosed") | K8: GRC & penetration testing
B9: 2025 | C9: Solsoft Group | D9: UK | E9: Ekco (Ireland MSP) | F9: Undisclosed | G9: Small | H9: Undisclosed | I9: =IFERROR(F9/G9,"Undisclosed") | J9: =IFERROR(F9/H9,"Undisclosed") | K9: MSP for SMEs
B10: 2023 | C10: BJSS | D10: UK | E10: CGI Inc | F10: 700 | G10: 301 | H10: 54 | I10: =IFERROR(F10/G10,"Undisclosed") | J10: =IFERROR(F10/H10,"Undisclosed") | K10: Digital transformation consulting
B11: 2022 | C11: Planalyse BV | D11: Netherlands | E11: Kainos Group | F11: Undisclosed | G11: Small | H11: Undisclosed | I11: =IFERROR(F11/G11,"Undisclosed") | J11: =IFERROR(F11/H11,"Undisclosed") | K11: Workday Adaptive Planning
B12: 2022 | C12: Blackline Group Inc | D12: USA | E12: Kainos Group | F12: Undisclosed | G12: Small | H12: Undisclosed | I12: =IFERROR(F12/G12,"Undisclosed") | J12: =IFERROR(F12/H12,"Undisclosed") | K12: Workday Strategic Sourcing
B13: 2025 | C13: CyberCrowd | D13: UK | E13: Limerston Capital (PE) | F13: Undisclosed | G13: Small | H13: Undisclosed | I13: =IFERROR(F13/G13,"Undisclosed") | J13: =IFERROR(F13/H13,"Undisclosed") | K13: Cybersecurity consultancy
B14: 2025 | C14: DigitalXRAID | D14: UK | E14: Limerston Capital (PE) | F14: Undisclosed | G14: Small | H14: Undisclosed | I14: =IFERROR(F14/G14,"Undisclosed") | J14: =IFERROR(F14/H14,"Undisclosed") | K14: Managed security (MSSP)
B15: 2025 | C15: 40fi | D15: UK | E15: Vorboss | F15: Undisclosed | G15: Small-mid | H15: Undisclosed | I15: =IFERROR(F15/G15,"Undisclosed") | J15: =IFERROR(F15/H15,"Undisclosed") | K15: Managed cybersecurity
B16: 2025 | C16: Armadillo Managed Services | D16: UK | E16: Transputec | F16: Undisclosed | G16: Small-mid | H16: Undisclosed | I16: =IFERROR(F16/G16,"Undisclosed") | J16: =IFERROR(F16/H16,"Undisclosed") | K16: Cyber resilience & infrastructure
B17: 2024 | C17: Technique Ltd | D17: UK | E17: Pixel Holdco (Chiltern PE) | F17: Undisclosed | G17: Small-mid | H17: Undisclosed | I17: =IFERROR(F17/G17,"Undisclosed") | J17: =IFERROR(F17/H17,"Undisclosed") | K17: IT managed services
B18: 2024 | C18: Elastacloud | D18: UK | E18: Acora | F18: Undisclosed | G18: Small-mid | H18: Undisclosed | I18: =IFERROR(F18/G18,"Undisclosed") | J18: =IFERROR(F18/H18,"Undisclosed") | K18: Data & AI for enterprises
B19: 2024 | C19: Engine B | D19: UK | E19: CLA UK | F19: Undisclosed | G19: Small | H19: Undisclosed | I19: =IFERROR(F19/G19,"Undisclosed") | J19: =IFERROR(F19/H19,"Undisclosed") | K19: Generative AI solutions
B20: 2024 | C20: 3DOT Solutions | D20: UK | E20: Nortal | F20: Undisclosed | G20: Small | H20: Undisclosed | I20: =IFERROR(F20/G20,"Undisclosed") | J20: =IFERROR(F20/H20,"Undisclosed") | K20: UK Armed Forces cyber
B21: 2024 | C21: Cyphra | D21: UK | E21: Pixel Holdco (Chiltern PE) | F21: Undisclosed | G21: Small | H21: Undisclosed | K21: Cybersecurity specialist
B23: 25th Percentile | J23: =QUARTILE.INC(J4:J20,1)
B24: Median
B25: 75th Percentile
